<mujocoinclude>
    <body name="lift_link" pos="0 0 0.021">
    <inertial pos="0.036836 0.002225 0.038434"  mass="2.512439" fullinertia='0.21937 0.57132 0.72996 -0.000791 0.002411 0.000164'/>
    <!-- <joint name="lift_joint" pos="0 0 0" axis="0 0 -1" type="slide" limited="true" range="0 0.185"/> -->
    <joint name="lift_joint" pos="0 0 0" axis="0 0 -1" type="slide" limited="true" range="0 0.185"/>
    <geom type="mesh" rgba="0.792157 0.819608 0.933333 1" mesh="lift_link" friction="1 0.5 0.0001" solimp="0.9 .99 .0001" solref=".001 1" />

     <body name="button1" pos="0.175 0.11 0.02">
      <inertial pos="0.175 0.11 0.02" mass="0.0001" diaginertia="0 0 0" />
      <geom type="box" size="0.01 0.01 0.02" rgba="0 1 0 0"/>
      <site name="site_bforcesensor1" type="cylinder" rgba="0 0 0 1" size="0.025 0.01" pos="0 0 0"/>
      </body>

      <body name="button2" pos="0.175 0 0.020">
      <inertial pos="0.175 0 0.020" mass="0.0001" diaginertia="0 0 0" />
      <geom type="box" size="0.01 0.01 0.020" rgba="0 1 0 0"/>
      <site name="site_bforcesensor2" type="cylinder" rgba="0 0 0 1" size="0.025 0.01" pos="0 0 0"/>
      </body>

      <body name="button3" pos="0.175 -0.11 0.020">
      <inertial pos="0.175 -0.11 0.020" mass="0.0001" diaginertia="0 0 0" />
      <geom type="box" size="0.01 0.01 0.020" rgba="0 1 0 0"/>
      <site name="site_bforcesensor3" type="cylinder" rgba="0 0 0 1" size="0.025 0.01" pos="0 0 0"/>
      </body>

      <body name="button4" pos="0 0.17 0.02">
      <inertial pos="0 0.17 0.02" mass="0.0001" diaginertia="0 0 0" />
      <geom type="box" size="0.01 0.01 0.02" rgba="0 1 0 0"/>
      <site name="site_bforcesensor4" type="cylinder" rgba="0 0 0 1" size="0.025 0.01" pos="0 0 0"/>
      </body>

      <body name="button5" pos="0 0 0.020">
      <inertial pos="0 0 0.020" mass="0.0001" diaginertia="0 0 0" />
      <geom type="box" size="0.19 0.15 0.025" rgba="0 1 0 0" margin="0.001" condim="3" friction="1 0.5 0.0001" solimp="0.9 .99 .0001" solref=".001 1"/>
      <site name="site_bforcesensor5" type="cylinder" rgba="0 0 0 1" size="0.025 0.01" pos="0 0 0"/>
      </body>

      <body name="button6" pos="0 -0.17 0.020">
      <inertial pos="0 -0.17 0.020" mass="0.0001" diaginertia="0 0 0" />
      <geom type="box" size="0.01 0.01 0.020" rgba="0 1 0 0"/>
      <site name="site_bforcesensor6" type="cylinder" rgba="0 0 0 1" size="0.025 0.01" pos="0 0 0"/>
      </body>

      <body name="button7" pos="-0.175 0.11 0.02">
      <inertial pos="-0.175 0.11 0.02" mass="0.0001" diaginertia="0 0 0" />
      <geom type="box" size="0.01 0.01 0.02" rgba="0 1 0 0"/>
      <site name="site_bforcesensor7" type="cylinder" rgba="0 0 0 1" size="0.025 0.01" pos="0 0 0"/>
      </body>

      <body name="button8" pos="-0.175 0 0.020">
      <inertial pos="-0.175 0 0.020" mass="0.0001" diaginertia="0 0 0" />
      <geom type="box" size="0.01 0.01 0.020" rgba="0 1 0 0"/>
      <site name="site_bforcesensor8" type="cylinder" rgba="0 0 0 1" size="0.025 0.01" pos="0 0 0"/>
      </body>

      <body name="button9" pos="-0.175 -0.11 0.020">
      <inertial pos="-0.175 -0.11 0.020" mass="0.0001" diaginertia="0 0 0" />
      <geom type="box" size="0.01 0.01 0.020" rgba="0 1 0 0"/>
      <site name="site_bforcesensor9" type="cylinder" rgba="0 0 0 1" size="0.025 0.01" pos="0 0 0"/>
      </body>

    </body>
</mujocoinclude>