    <mujoco model="robot">
    <compiler angle="radian"/>
    <size njmax="500" nconmax="100"/>
    <default/>
    <asset>
    <mesh name="base_link" file="base_link.STL"/>
    <mesh name="left_1" file="left_1.STL"/>
    <mesh name="left_2" file="left_2.STL"/>
    <mesh name="left_3" file="left_3.STL"/>
    <mesh name="left_4" file="left_4.STL"/>
    <mesh name="left_5" file="left_5.STL"/>
    <mesh name="left_61" file="left_61.STL"/>
    <mesh name="left_7" file="left_7.STL"/>
    <mesh name="right_1" file="right_1.STL"/>
    <mesh name="right_2" file="right_2.STL"/>
    <mesh name="right_3" file="right_3.STL"/>
    <mesh name="right_4" file="right_4.STL"/>
    <mesh name="right_5" file="right_5.STL"/>
    <mesh name="right_61" file="right_61.STL"/>
    <mesh name="right_7" file="right_7.STL"/>
    <mesh name="lift_link" file="lift_link.STL"/>
    <texture type="skybox" builtin="gradient" rgb1="0.3 0.5 0.7" rgb2="0 0 0" width="512" height="512" />
	  <texture name="texplane" type="2d" builtin="checker" rgb1=".2 .3 .4" rgb2=".1 0.15 0.2" width="512" height="512" mark="cross" markrgb=".8 .8 .8" />
	  <material name="matplane" reflectance="0.3" texture="texplane" texrepeat="1 1" texuniform="true" />
    </asset>
    <option timestep="0.001" iterations="11" tolerance="1e-10" solver="Newton" jacobian="dense" cone="pyramidal"/>
    <worldbody>
    <light directional="true" diffuse=".4 .4 .4" specular="0.1 0.1 0.1" pos="0 0 5.0" dir="0 0 -1" castshadow="false" />
	  <light directional="true" diffuse=".6 .6 .6" specular="0.2 0.2 0.2" pos="0 0 4" dir="0 0 -1" />
	  <geom name="floor" pos="0 0 0" size="15 15 1" type="plane" material="matplane" margin="0.001" condim="3" friction="2 0.5 0.0001" solimp="0.9 .99 .0001" solref=".001 1" />


       <body name="box1" pos="0.4 0.5 0.3">
       <inertial pos="0 0 0" mass="0.0001" diaginertia="0 0 0" />
       <geom type="box" pos="0 0 0" size="0.025 0.025 0.3" rgba="255 0 0 1"   condim="3" margin="0.0001" friction="2 0.5 0.0001" solimp="0.9 .99 .0001" solref=".001 1"/> 
       </body>

       <body name="box2" pos="0.4 -0.5 0.3">
       <inertial pos="0 0 0" mass="0.0001" diaginertia="0 0 0" />
       <geom type="box" pos="0 0 0" size="0.025 0.025 0.3" rgba="255 0 0 1"   condim="3" margin="0.0001" friction="2 0.5 0.0001" solimp="0.9 .99 .0001" solref=".001 1"/> 
       </body>

       <body name="box3" pos="0.8 0.5 0.3">
       <inertial pos="0 0 0" mass="0.0001" diaginertia="0 0 0" />
       <geom type="box" pos="0 0 0" size="0.025 0.025 0.3" rgba="255 0 0 1"   condim="3" margin="0.0001" friction="2 0.5 0.0001" solimp="0.9 .99 .0001" solref=".001 1"/> 
       </body>

       <body name="box4" pos="0.8 -0.5 0.3">
       <inertial pos="0 0 0" mass="0.0001" diaginertia="0 0 0" />
       <geom type="box" pos="0 0 0" size="0.025 0.025 0.3" rgba="255 0 0 1"   condim="3" margin="0.0001" friction="2 0.5 0.0001" solimp="0.9 .99 .0001" solref=".001 1"/> 
       </body>

       <body name="box5" pos="0.6 0 0.65">
       <inertial pos="0 0 0" mass="0.0001" diaginertia="0 0 0" />
       <geom type="box" pos="0 0 0" size="0.3 0.8 0.05" rgba="255 0 0 1"   condim="3" margin="0.0001" friction="2 0.5 0.0001" solimp="0.9 .99 .0001" solref=".001 1"/> 
       </body>

       <body name="box6" pos="0.55 0.3 0.75">
       <freejoint name="root1"/>
       <inertial pos="0 0 0" mass="0.6" fullinertia='0.00173492 0.00180332 0.00091131 0 0 0'/>
       <geom type="box" pos="0 0 0" size="0.05 0.1 0.05" rgba="0 255 0 1"   condim="3" margin="0.0001" friction="2 0.5 0.0001" solimp="0.9 .99 .0001" solref=".001 1"/> 

       <body name="box7" pos="0 0.15 0.028">
       <inertial pos="0 0 0" mass="0.2" fullinertia='0.00173492 0.00180332 0.00091131 0 0 0'/>
       <geom type="box" pos="0 0 0" size="0.05 0.05 0.02" rgba="0 255 0 1"   condim="3" margin="0.0001" friction="2 0.5 0.0001" solimp="0.9 .99 .0001" solref=".001 1"/> 
       </body>

       <body name="box8" pos="0 -0.15 0.028">
       <inertial pos="0 0 0" mass="0.2" fullinertia='0.00173492 0.00180332 0.00091131 0 0 0'/>
       <geom type="box" pos="0 0 0" size="0.05 0.05 0.02" rgba="0 255 0 1"   condim="3" margin="0.0001" friction="2 0.5 0.0001" solimp="0.9 .99 .0001" solref=".001 1"/> 
       </body>
       </body>

       <body name="base_link" pos="0 0 0.0382" euler="0 0 0">
       <freejoint name="root"/>
       <inertial pos="0.000669 0.002809 0.252536" mass="8.98058263" fullinertia='0.173492 0.180332 0.091131 0.000152 0.005106 -0.002'/>
       <geom type="mesh" rgba="0.792157 0.819608 0.933333 1" mesh="base_link" condim="3" margin="0.0001" friction="2 0.5 0.0001" solimp="0.9 .99 .0001" solref=".001 1"/>
 
       <body name="bbutton1" pos="0.14 0.155 0.019">
       <inertial pos="0 0 0" mass="0.0001" diaginertia="0 0 0" />
       <geom type="box" size="0.02 0.02 0.018" rgba="0 1 0 1"/>
       <site name="site_bbforcesensor1" type="cylinder" rgba="0 0 0 1" size="0.025 0.01" pos="0 0 0"/>
       </body>

       <body name="bbutton2" pos="0.14 -0.155 0.019">
       <inertial pos="0 0 0" mass="0.0001" diaginertia="0 0 0" />
       <geom type="box" size="0.02 0.02 0.018" rgba="0 1 0 1"/>
       <site name="site_bbforcesensor2" type="cylinder" rgba="0 0 0 1" size="0.025 0.01" pos="0 0 0"/>
       </body>

       <body name="bbutton3" pos="-0.14 0.155 0.019">
       <inertial pos="0 0 0" mass="0.0001" diaginertia="0 0 0" />
       <geom type="box" size="0.02 0.02 0.018" rgba="0 1 0 1"/>
       <site name="site_bbforcesensor3" type="cylinder" rgba="0 0 0 1" size="0.025 0.01" pos="0 0 0"/>
       </body>

      <body name="bbutton4" pos="-0.14 -0.155 0.019">
      <inertial pos="0 0 0" mass="0.0001" diaginertia="0 0 0" />
      <geom type="box" size="0.02 0.02 0.018" rgba="0 1 0 1"/>
      <site name="site_bbforcesensor4" type="cylinder" rgba="0 0 0 1" size="0.025 0.01" pos="0 0 0"/>
      </body>

      <body name="mbutton1" pos="0.18 0 0.12">
      <inertial pos="0 0 0" mass="0.0001" diaginertia="0 0 0" />
      <geom type="box" size="0.01 0.01 0.01" rgba="0 1 0 1" condim="3" margin="0.0001" friction="2 0.5 0.0001" solimp="0.9 .99 .0001" solref=".001 1"/>
      <site name="site_mbforcesensor1" type="cylinder" rgba="0 0 0 1" size="0.025 0.01" pos="0 0 0"/>
      </body>

      <body name="mbutton2" pos="-0.18 0 0.12">
      <inertial pos="0 0 0" mass="0.0001" diaginertia="0 0 0" />
      <geom type="box" size="0.01 0.01 0.01" rgba="0 1 0 1" condim="3" margin="0.0001" friction="2 0.5 0.0001" solimp="0.9 .99 .0001" solref=".001 1"/>
      <site name="site_mbforcesensor2" type="cylinder" rgba="0 0 0 1" size="0.025 0.01" pos="0 0 0"/>
      </body>

      <body name="ubutton1" pos="0.18 0 0.47">
      <inertial pos="0 0 0" mass="0.0001" diaginertia="0 0 0" />
      <geom type="box" size="0.01 0.01 0.019" rgba="0 1 0 1"/>
      <site name="site_ubforcesensor1" type="cylinder" rgba="0 0 0 1" size="0.025 0.01" pos="0 0 0"/>
      </body>

      <body name="ubutton2" pos="-0.18 0 0.47">
      <inertial pos="0 0 0" mass="0.0001" diaginertia="0 0 0" />
      <geom type="box" size="0.01 0.01 0.019" rgba="0 1 0 1"/>
      <site name="site_ubforcesensor2" type="cylinder" rgba="0 0 0 1" size="0.025 0.01" pos="0 0 0"/>
      </body>
      
    <body name="left_1" pos="0 0.143 0.382">
    <inertial pos="-2.1376e-07 -0.025186 0.021108"  mass="1.3384326" fullinertia='0.012661 0.0056135 0.011817 0 0 -0.00021122'/>
     
    <joint name="left_joint_1" pos="0 0 0" axis="0 1 0" limited="true" range="-3.106686 3.106686"/>
    <geom type="mesh" rgba="0.792157 0.819608 0.933333 1" mesh="left_1"/>
     <site name="site_handforcesensor1" type="cylinder" rgba="0 0 0 1" size="0.025 0.01" pos="0 0 0"/>

    <body name="left_2" pos="0 0.102 -0.016461">
    <inertial pos="-0.15226 -0.0062025 0.00000060139" mass="1.95009404" fullinertia='0.0063254 0.019528 0.020527 -0.00042163 0 0'/>
     
    <joint name="left_joint_2" pos="0 0 0" axis="0 0 -1" limited="true" range="-2.268928 2.268928"/>
    <geom type="mesh" rgba="0.792157 0.819608 0.933333 1" mesh="left_2"/>
     
    <body name="left_3" pos="0 0.256 0.0035251">
    <inertial pos="-0.0000050421 0.010569 -0.059593" mass="0.6537103"  fullinertia='0.0063737 0.0061418 0.0015648 0 0 -0.00014461'/>
     
    <joint name="left_joint_3" pos="0 0 0" axis="0 0 -1" limited="true" range="-2.35619449 2.35619449"/>
    <geom type="mesh" rgba="0.792157 0.819608 0.933333 1" mesh="left_3"/>
     
    <body name="left_4" pos="0 0.1285 0.013236">
    <inertial pos="-0.0000011466 -0.021541 -0.018041"  mass="0.540812539184" fullinertia='0.028594 0.011989 0.026273 0 0 0.000044238'/>
     
    <joint name="left_joint_4" pos="0 0 0" axis="0 1 0" limited="true" range="-3.106686 3.106686"/>
    <geom type="mesh" rgba="0.792157 0.819608 0.933333 1" mesh="left_4"/>
     
    <body name="left_5" pos="0 0.0815 -0.012136">
    <inertial pos="-0.0000034542 0.0073678 -0.059382"  mass="0.49382068965" fullinertia='0.035053 0.033447 0.010492 0 0 -0.00007824'/>
     
    <joint name="left_joint_5" pos="0 0 0" axis="0 0 -1" limited="true" range="-2.234 2.234"/>
    <geom type="mesh" rgba="0.792157 0.819608 0.933333 1" mesh="left_5"/>
     
    <body name="left_6" pos="0 0.115 0.012436">
    <inertial pos="0.000082 0.071604 -0.003027"  mass="0.7" fullinertia='0.1064 0.0655 0.0732 0 0 0.000048'/>
     
    <!-- <joint name="left_joint_6" pos="0 0 0" axis="0 1 0" limited="true" range="-6.2831853 6.2831853"/>
    <geom type="mesh" rgba="0.792157 0.819608 0.933333 1" mesh="left_61" margin="0.0001" condim="3" friction="1 0.5 0.0001" solimp="0.9 .99 .0001" solref=".001 1" />
       <site name="site_handforcesensor3" type="cylinder" rgba="0 0 0 1" size="0.025 0.01" pos="0 0 0"/> -->

    <joint name="left_joint_6" pos="0 0 0" axis="0 1 0" limited="true" range="-6.2831853 6.2831853"/>
    <geom type="box" rgba="0.792157 0.819608 0.933333 1" pos="0 0.054 0" size="0.037 0.054 0.05" margin="0.0001" condim="3" friction="1 0.5 0.0001" solimp="0.9 .99 .0001" solref=".001 1" />
     <geom type="box" rgba="0.792157 0.819608 0.933333 1" pos="0 0.133 0.0425" size="0.037 0.025 0.0075" margin="0.0001" condim="3" friction="1 0.5 0.0001" solimp="0.9 .99 .0001" solref=".001 1" />
     
      <body name="handforcesensor3" pos="0 0.133 0.0425">
      <inertial pos="0 0 0" mass="0.0001" diaginertia="0 0 0" />
      <geom type="box" size="0.01 0.01 0.01" rgba="0 1 0 1"/>
      <site name="site_handforcesensor3" type="cylinder" rgba="0 0 0 1" size="0.025 0.01" pos="0 0 0"/>
      </body>

    <body name="left_7" pos="0 0.101 -0.0255">
    <inertial pos="0.000316 0.002426 0.003507" mass="0.11005" fullinertia='0.69 0.4 1.02 0 0 0'/>
     
    <!-- <joint name="left_joint_7" pos="0 0 0" axis="0 0 -1" type="slide" limited="true" range="-0.04 0"/>
    <geom type="mesh" rgba="0.792157 0.819608 0.933333 1" mesh="left_7" margin="0.001" condim="3" friction="1 0.5 0.0001" solimp="0.9 .99 .0001" solref=".001 1"/> -->

    <joint name="left_joint_7" pos="0 0 0" axis="0 0 -1" type="slide" limited="true" range="-0.04 0.04"/>
    <geom type="box" rgba="0.792157 0.819608 0.933333 1" pos="0 0.03 0" size="0.037 0.03 0.0075" margin="0.0001" condim="3" friction="1 0.5 0.0001" solimp="0.9 .99 .0001" solref=".001 1" />
    <!-- <geom type="box" rgba="0.792157 0.819608 0.933333 1" pos="0 0.055 0.01" size="0.037 0.005 0.005" margin="0.0001" condim="3" friction="1 0.5 0.0001" solimp="0.9 .99 .0001" solref=".001 1" /> -->
 
    </body>
    </body>
    </body>
    </body>
    </body>
    </body>
    </body>
    <body name="right_1" pos="0 -0.145 0.382">
    <inertial pos="2.1376e-07 0.025186 0.021108"  mass="1.3384326" fullinertia='0.012661 0.0056135 0.011817 0 0 0.00021122'/>

    <joint name="right_joint_1" pos="0 0 0" axis="0 -1 0" limited="true" range="-3.106686 3.106686"/>
    <geom type="mesh" rgba="0.792157 0.819608 0.933333 1" mesh="right_1"/>
    <site name="site_handforcesensor2" type="cylinder" rgba="0 0 0 1" size="0.025 0.01" pos="0 0 0"/>

    <body name="right_2" pos="0 -0.102 -0.016461">
    <inertial pos="0.15226 0.0062025 0.00000060139" mass="1.95009404" fullinertia='0.0063254 0.019528 0.020527 0.00042163 0 0'/>
       
    <joint name="right_joint_2" pos="0 0 0" axis="0 0 -1" limited="true" range="-2.268928 2.268928"/>
    <geom type="mesh" rgba="0.792157 0.819608 0.933333 1" mesh="right_2"/>

    <body name="right_3" pos="0 -0.256 0.0035251">
   <inertial pos="0.0000050421 -0.010569 -0.059593" mass="0.6537103"  fullinertia='0.0063737 0.0061418 0.0015648 0 0 0.00014461'/>

    <joint name="right_joint_3" pos="0 0 0" axis="0 0 -1" limited="true" range="-2.35619449 2.35619449"/>
    <geom type="mesh" rgba="0.792157 0.819608 0.933333 1" mesh="right_3"/>

    <body name="right_4" pos="0 -0.1285 0.013236">
     <inertial pos="0.0000011466 0.021541 -0.018041"  mass="0.540812539" fullinertia='0.028594 0.011989 0.026273 0 0 -0.000044238'/>

    <joint name="right_joint_4" pos="0 0 0" axis="0 -1 0"  limited="true" range="-3.106686 3.106686"/>
    <geom type="mesh" rgba="0.792157 0.819608 0.933333 1" mesh="right_4"/>

    <body name="right_5" pos="0 -0.0815 -0.012136">
    <inertial pos="0.0000034542 -0.0073678 -0.059382"  mass="0.493820689655" fullinertia='0.035053 0.033447 0.010492 0 0 0.00007824'/>
             
    <joint name="right_joint_5" pos="0 0 0" axis="0 0 -1" limited="true" range="-2.234 2.234"/>
    <geom type="mesh" rgba="0.792157 0.819608 0.933333 1" mesh="right_5"/>

    <body name="right_6" pos="0.00023669 -0.115 0.012436">
     <inertial pos="-0.000082 -0.071604 -0.003027"  mass="0.7" fullinertia='0.1064 0.0655 0.0732 0 0 -0.000048'/>
               
    <joint name="right_joint_6" pos="0 0 0" axis="0 -1 0" limited="true" range="-6.2831853 6.2831853"/>
    <!-- <geom type="mesh" rgba="0.792157 0.819608 0.933333 1" mesh="right_61" margin="0.0001" condim="3" friction="1 0.5 0.0001" solimp="0.9 .99 .0001" solref=".001 1" /> -->
     <geom type="box" rgba="0.792157 0.819608 0.933333 1" pos="0 -0.054 0" size="0.037 0.054 0.05" margin="0.0001" condim="3" friction="1 0.5 0.0001" solimp="0.9 .99 .0001" solref=".001 1" />
     <geom type="box" rgba="0.792157 0.819608 0.933333 1" pos="0 -0.133 0.0425" size="0.037 0.025 0.0075" margin="0.0001" condim="3" friction="1 0.5 0.0001" solimp="0.9 .99 .0001" solref=".001 1" />
     
     <body name="handforcesensor4" pos="0 -0.133 0.0425">
      <inertial pos="0 0 0" mass="0.0001" diaginertia="0 0 0" />
      <geom type="box" size="0.01 0.01 0.01" rgba="0 1 0 1"/>
      <site name="site_handforcesensor4" type="cylinder" rgba="0 0 0 1" size="0.025 0.01" pos="0 0 0"/>
      </body>

                
    <body name="right_7" pos="-0.00023783 -0.101 -0.0255">
      <inertial pos="-0.000316 -0.002426 0.003507" mass="0.11005" fullinertia='0.69 0.4 1.02 0 0 0'/>
                  
    <joint name="right_joint_7" pos="0 0 0" axis="0 0 -1" type="slide" limited="true" range="-0.04 0.04"/>
    <!-- <geom type="mesh" rgba="0.792157 0.819608 0.933333 1" mesh="right_7" margin="0.0001" condim="3" friction="1 0.5 0.0001" solimp="0.9 .99 .0001" solref=".001 1"/> -->
    <geom type="box" rgba="0.792157 0.819608 0.933333 1" pos="0 -0.03 0" size="0.037 0.03 0.0075" margin="0.0001" condim="3" friction="1 0.5 0.0001" solimp="0.9 .99 .0001" solref=".001 1" />
    <!-- <geom type="box" rgba="0.792157 0.819608 0.933333 1" pos="0 -0.055 0.01" size="0.037 0.005 0.005" margin="0.0001" condim="3" friction="1 0.5 0.0001" solimp="0.9 .99 .0001" solref=".001 1" /> -->
 
    </body>
    </body>
    </body>
    </body>
    </body>
    </body>
    </body>
    <body name="lift_link" pos="0 0 0.021">
    <inertial pos="0.036836 0.002225 0.038434"  mass="4.012439" fullinertia='0.21937 0.57132 0.72996 -0.000791 0.002411 0.000164'/>

    <joint name="lift_joint" pos="0 0 0" axis="0 0 -1" type="slide" limited="true" range="0 0.185"/>
    <geom type="mesh" rgba="0.792157 0.819608 0.933333 1" mesh="lift_link" friction="2 0.5 0.0001" solimp="0.9 .99 .0001" solref=".001 1" />

     <body name="button1" pos="0.175 0.11 0.02">
      <inertial pos="0.175 0.11 0.02" mass="0.0001" diaginertia="0 0 0" />
      <geom type="box" size="0.01 0.01 0.02" rgba="0 1 0 1" condim="3" margin="0.0001" friction="2 0.5 0.0001" solimp="0.9 .99 .0001" solref=".001 1"/>
      <site name="site_bforcesensor1" type="cylinder" rgba="0 0 0 1" size="0.025 0.01" pos="0 0 0"/>
      </body>

      <body name="button2" pos="0.175 0 0.020">
      <inertial pos="0.175 0 0.020" mass="0.0001" diaginertia="0 0 0" />
      <geom type="box" size="0.01 0.01 0.020" rgba="0 1 0 1" condim="3" margin="0.0001" friction="2 0.5 0.0001" solimp="0.9 .99 .0001" solref=".001 1"/>
      <site name="site_bforcesensor2" type="cylinder" rgba="0 0 0 1" size="0.025 0.01" pos="0 0 0"/>
      </body>

      <body name="button3" pos="0.175 -0.11 0.020">
      <inertial pos="0.175 -0.11 0.020" mass="0.0001" diaginertia="0 0 0" />
      <geom type="box" size="0.01 0.01 0.020" rgba="0 1 0 1" condim="3" margin="0.0001" friction="2 0.5 0.0001" solimp="0.9 .99 .0001" solref=".001 1"/>
      <site name="site_bforcesensor3" type="cylinder" rgba="0 0 0 1" size="0.025 0.01" pos="0 0 0"/>
      </body>

      <body name="button4" pos="0 0.17 0.02">
      <inertial pos="0 0.17 0.02" mass="0.0001" diaginertia="0 0 0" />
      <geom type="box" size="0.01 0.01 0.02" rgba="0 1 0 1" condim="3" margin="0.0001" friction="2 0.5 0.0001" solimp="0.9 .99 .0001" solref=".001 1"/>
      <site name="site_bforcesensor4" type="cylinder" rgba="0 0 0 1" size="0.025 0.01" pos="0 0 0"/>
      </body>

      <body name="button5" pos="0 0 0.020">
      <inertial pos="0 0 0.020" mass="0.0001" diaginertia="0 0 0" />
      <geom type="box" size="0.01 0.01 0.020" rgba="0 1 0 1" condim="3" margin="0.0001" friction="2 0.5 0.0001" solimp="0.9 .99 .0001" solref=".001 1"/>
      <site name="site_bforcesensor5" type="cylinder" rgba="0 0 0 1" size="0.025 0.01" pos="0 0 0"/>
      </body>

      <body name="button6" pos="0 -0.17 0.020">
      <inertial pos="0 -0.17 0.020" mass="0.0001" diaginertia="0 0 0" />
      <geom type="box" size="0.01 0.01 0.020" rgba="0 1 0 1" condim="3" margin="0.0001" friction="2 0.5 0.0001" solimp="0.9 .99 .0001" solref=".001 1"/>
      <site name="site_bforcesensor6" type="cylinder" rgba="0 0 0 1" size="0.025 0.01" pos="0 0 0"/>
      </body>

           <body name="button7" pos="-0.175 0.11 0.02">
      <inertial pos="-0.175 0.11 0.02" mass="0.0001" diaginertia="0 0 0" />
      <geom type="box" size="0.01 0.01 0.02" rgba="0 1 0 1" condim="3" margin="0.0001" friction="2 0.5 0.0001" solimp="0.9 .99 .0001" solref=".001 1"/>
      <site name="site_bforcesensor7" type="cylinder" rgba="0 0 0 1" size="0.025 0.01" pos="0 0 0"/>
      </body>

      <body name="button8" pos="-0.175 0 0.020">
      <inertial pos="-0.175 0 0.020" mass="0.0001" diaginertia="0 0 0" />
      <geom type="box" size="0.01 0.01 0.020" rgba="0 1 0 1" condim="3" margin="0.0001" friction="2 0.5 0.0001" solimp="0.9 .99 .0001" solref=".001 1"/>
      <site name="site_bforcesensor8" type="cylinder" rgba="0 0 0 1" size="0.025 0.01" pos="0 0 0"/>
      </body>

      <body name="button9" pos="-0.175 -0.11 0.020">
      <inertial pos="-0.175 -0.11 0.020" mass="0.0001" diaginertia="0 0 0" />
      <geom type="box" size="0.01 0.01 0.020" rgba="0 1 0 1" condim="3" margin="0.0001" friction="2 0.5 0.0001" solimp="0.9 .99 .0001" solref=".001 1"/>
      <site name="site_bforcesensor9" type="cylinder" rgba="0 0 0 1" size="0.025 0.01" pos="0 0 0"/>
      </body>

    </body>
    </body>
    </worldbody>

    <contact>

		<exclude body1="base_link" body2="left_1"/>
		<exclude body1="base_link" body2="left_2"/>
		<exclude body1="base_link" body2="left_3"/>
		<exclude body1="base_link" body2="left_4"/>
		<exclude body1="base_link" body2="left_5"/>
		<exclude body1="base_link" body2="left_6"/>

		<exclude body1="base_link" body2="right_1"/>
		<exclude body1="base_link" body2="right_2"/>
		<exclude body1="base_link" body2="right_3"/>
		<exclude body1="base_link" body2="right_4"/>
		<exclude body1="base_link" body2="right_5"/>
		<exclude body1="base_link" body2="right_6"/>

    <exclude body1="base_link" body2="lift_link"/>
    		<exclude body1="base_link" body2="left_7"/>
        		<exclude body1="base_link" body2="right_7"/>

		<exclude body1="left_1" body2="left_2"/>
		<exclude body1="left_1" body2="left_3"/>
		<exclude body1="left_1" body2="left_4"/>
		<exclude body1="left_1" body2="left_5"/>
		<exclude body1="left_1" body2="left_6"/>

		<exclude body1="left_2" body2="left_3"/>
		<exclude body1="left_2" body2="left_4"/>
		<exclude body1="left_2" body2="left_5"/>
		<exclude body1="left_2" body2="left_6"/>

		<exclude body1="left_3" body2="left_4"/>
		<exclude body1="left_3" body2="left_5"/>
		<exclude body1="left_3" body2="left_6"/>

		<exclude body1="left_4" body2="left_5"/>
		<exclude body1="left_4" body2="left_6"/>

		<exclude body1="left_5" body2="left_6"/>
    		<exclude body1="left_1" body2="left_7"/> 
		 <exclude body1="left_5" body2="left_7"/>
		<exclude body1="left_6" body2="left_7"/> 
    		 <exclude body1="left_2" body2="left_7"/> 
        		<exclude body1="left_3" body2="left_7"/> 
            		 <exclude body1="left_4" body2="left_7"/>
		
		<exclude body1="right_1" body2="right_2"/>
		<exclude body1="right_1" body2="right_3"/>
		<exclude body1="right_1" body2="right_4"/>
		<exclude body1="right_1" body2="right_5"/>
		<exclude body1="right_1" body2="right_6"/>
		<exclude body1="right_1" body2="right_7"/>
		<exclude body1="right_2" body2="right_3"/>
		<exclude body1="right_2" body2="right_4"/>
		<exclude body1="right_2" body2="right_5"/>
		<exclude body1="right_2" body2="right_6"/>
		<exclude body1="right_2" body2="right_7"/>
		<exclude body1="right_3" body2="right_4"/>
		<exclude body1="right_3" body2="right_5"/>
		<exclude body1="right_3" body2="right_6"/>
		<exclude body1="right_3" body2="right_7"/>
		<exclude body1="right_4" body2="right_5"/>
		<exclude body1="right_4" body2="right_6"/>
		<exclude body1="right_4" body2="right_7"/>
		<exclude body1="right_5" body2="right_6"/>
		<exclude body1="right_5" body2="right_7"/>
		<exclude body1="right_6" body2="right_7"/>

    <exclude body1="lift_link" body2="left_1"/>
		<exclude body1="lift_link" body2="left_2"/>
		<exclude body1="lift_link" body2="left_3"/>
		<exclude body1="lift_link" body2="left_4"/>
		<exclude body1="lift_link" body2="left_5"/>
		<exclude body1="lift_link" body2="left_6"/>
		<exclude body1="lift_link" body2="left_7"/>
		<exclude body1="lift_link" body2="right_1"/>
		<exclude body1="lift_link" body2="right_2"/>
		<exclude body1="lift_link" body2="right_3"/>
		<exclude body1="lift_link" body2="right_4"/>
		<exclude body1="lift_link" body2="right_5"/>
		<exclude body1="lift_link" body2="right_6"/>
		<exclude body1="lift_link" body2="right_7"/>

    </contact>
	  <actuator>
		<motor    name="left_joint_1"      gear="1"    joint="left_joint_1"   	ctrllimited="true"    ctrlrange="-60 60"/>
		<motor    name="left_joint_2"      gear="1"    joint="left_joint_2"   	ctrllimited="true"    ctrlrange="-60 60"/>
		<motor    name="left_joint_3"      gear="1"    joint="left_joint_3"  	  ctrllimited="true"    ctrlrange="-30 30"/>
		<motor    name="left_joint_4"      gear="1"    joint="left_joint_4"   	ctrllimited="true"    ctrlrange="-30 30"/>
		<motor    name="left_joint_5"      gear="1"    joint="left_joint_5"  	  ctrllimited="true"    ctrlrange="-60 60"/>
		<motor    name="left_joint_6"      gear="1"    joint="left_joint_6"  	  ctrllimited="true"    ctrlrange="-60 60"/>
		<motor    name="left_joint_7"      gear="1"    joint="left_joint_7"     ctrllimited="true"    ctrlrange="-2000 2000"/>
		<motor    name="right_joint_1"     gear="1"    joint="right_joint_1"    ctrllimited="true"    ctrlrange="-60 60"/>
		<motor    name="right_joint_2"     gear="1"    joint="right_joint_2"  	ctrllimited="true"    ctrlrange="-60 60"/>
		<motor    name="right_joint_3"     gear="1"    joint="right_joint_3"  	ctrllimited="true"    ctrlrange="-30 30"/>
		<motor    name="right_joint_4"     gear="1"    joint="right_joint_4"    ctrllimited="true"    ctrlrange="-30 30"/>
		<motor    name="right_joint_5"     gear="1"    joint="right_joint_5"  	ctrllimited="true"    ctrlrange="-60 60"/>
		<motor    name="right_joint_6"     gear="1"    joint="right_joint_6"  	ctrllimited="true"    ctrlrange="-60 60"/>
		<motor    name="right_joint_7"     gear="1"    joint="right_joint_7"    ctrllimited="true"    ctrlrange="-2000 2000"/>
    <motor    name="lift_joint"     gear="1"    joint="lift_joint"    ctrllimited="true"    ctrlrange="-12000 12000"/>
	  </actuator>

    <sensor>
    <torque name="bforcesensor1" site="site_bforcesensor1" cutoff="2000.0"/>
    <torque name="bforcesensor2" site="site_bforcesensor2" cutoff="2000.0"/> 
    <torque name="bforcesensor3" site="site_bforcesensor3" cutoff="2000.0"/>
    <torque name="bforcesensor4" site="site_bforcesensor4" cutoff="2000.0"/> 
    <torque name="bforcesensor5" site="site_bforcesensor5" cutoff="2000.0"/>
    <torque name="bforcesensor6" site="site_bforcesensor6" cutoff="2000.0"/> 
    <torque name="bforcesensor7" site="site_bforcesensor7" cutoff="2000.0"/>
    <torque name="bforcesensor8" site="site_bforcesensor8" cutoff="2000.0"/> 
    <torque name="bforcesensor9" site="site_bforcesensor9" cutoff="2000.0"/> 

    <torque name="bbforcesensor1" site="site_bbforcesensor1" cutoff="2000.0"/> 
    <torque name="bbforcesensor2" site="site_bbforcesensor2" cutoff="2000.0"/>
    <torque name="bbforcesensor3" site="site_bbforcesensor3" cutoff="2000.0"/> 
    <torque name="bbforcesensor4" site="site_bbforcesensor4" cutoff="2000.0"/> 

    <torque name="mbforcesensor1" site="site_mbforcesensor1" cutoff="2000.0"/> 
    <torque name="mbforcesensor2" site="site_mbforcesensor2" cutoff="2000.0"/> 

    <torque name="ubforcesensor1" site="site_ubforcesensor1" cutoff="2000.0"/> 
    <torque name="ubforcesensor2" site="site_ubforcesensor2" cutoff="2000.0"/> 

    <torque name="handforcesensor1" site="site_handforcesensor1" cutoff="2000.0"/> 
    <torque name="handforcesensor2" site="site_handforcesensor2" cutoff="2000.0"/> 

    <torque name="handforcesensor3" site="site_handforcesensor3" cutoff="2000.0"/> 
    <torque name="handforcesensor4" site="site_handforcesensor4" cutoff="2000.0"/> 
    </sensor>

    </mujoco>